A crash caused by the ``name`` argument added to asynchronous tasks in Python 3.13.3 has been corrected.
